Internal Server Error: /sms/api/gifts/
Traceback (most recent call last):
  File "/Users/zahed/Downloads/BestElectronics/smsCampaign/env/lib/python3.13/site-packages/django/core/handlers/exception.py", line 55, in inner
    response = get_response(request)
  File "/Users/zahed/Downloads/BestElectronics/smsCampaign/env/lib/python3.13/site-packages/django/core/handlers/base.py", line 197, in _get_response
    response = wrapped_callback(request, *callback_args, **callback_kwargs)
  File "/Users/zahed/Downloads/BestElectronics/smsCampaign/env/lib/python3.13/site-packages/django/views/decorators/csrf.py", line 65, in _view_wrapper
    return view_func(request, *args, **kwargs)
  File "/Users/zahed/Downloads/BestElectronics/smsCampaign/env/lib/python3.13/site-packages/django/views/generic/base.py", line 104, in view
    return self.dispatch(request, *args, **kwargs)
           ~~~~~~~~~~~~~^^^^^^^^^^^^^^^^^^^^^^^^^^
  File "/Users/zahed/Downloads/BestElectronics/smsCampaign/env/lib/python3.13/site-packages/rest_framework/views.py", line 509, in dispatch
    response = self.handle_exception(exc)
  File "/Users/zahed/Downloads/BestElectronics/smsCampaign/env/lib/python3.13/site-packages/rest_framework/views.py", line 469, in handle_exception
    self.raise_uncaught_exception(exc)
    ~~~~~~~~~~~~~~~~~~~~~~~~~~~~~^^^^^
  File "/Users/zahed/Downloads/BestElectronics/smsCampaign/env/lib/python3.13/site-packages/rest_framework/views.py", line 480, in raise_uncaught_exception
    raise exc
  File "/Users/zahed/Downloads/BestElectronics/smsCampaign/env/lib/python3.13/site-packages/rest_framework/views.py", line 506, in dispatch
    response = handler(request, *args, **kwargs)
  File "/Users/zahed/Downloads/BestElectronics/smsCampaign/campaign/views.py", line 87, in post
    gift_card = GiftCard.objects.get(product_code=product_code)
  File "/Users/zahed/Downloads/BestElectronics/smsCampaign/env/lib/python3.13/site-packages/django/db/models/manager.py", line 87, in manager_method
    return getattr(self.get_queryset(), name)(*args, **kwargs)
           ~~~~~~~~~~~~~~~~~~~~~~~~~~~~~~~~~~^^^^^^^^^^^^^^^^^
  File "/Users/zahed/Downloads/BestElectronics/smsCampaign/env/lib/python3.13/site-packages/django/db/models/query.py", line 652, in get
    raise self.model.MultipleObjectsReturned(
    ...<5 lines>...
    )
campaign.models.GiftCard.MultipleObjectsReturned: get() returned more than one GiftCard -- it returned 2!
"POST //sms/api/gifts/ HTTP/1.1" 500 102839
Internal Server Error: /sms/api/gifts/
Traceback (most recent call last):
  File "/Users/zahed/Downloads/BestElectronics/smsCampaign/env/lib/python3.13/site-packages/django/core/handlers/exception.py", line 55, in inner
    response = get_response(request)
  File "/Users/zahed/Downloads/BestElectronics/smsCampaign/env/lib/python3.13/site-packages/django/core/handlers/base.py", line 197, in _get_response
    response = wrapped_callback(request, *callback_args, **callback_kwargs)
  File "/Users/zahed/Downloads/BestElectronics/smsCampaign/env/lib/python3.13/site-packages/django/views/decorators/csrf.py", line 65, in _view_wrapper
    return view_func(request, *args, **kwargs)
  File "/Users/zahed/Downloads/BestElectronics/smsCampaign/env/lib/python3.13/site-packages/django/views/generic/base.py", line 104, in view
    return self.dispatch(request, *args, **kwargs)
           ~~~~~~~~~~~~~^^^^^^^^^^^^^^^^^^^^^^^^^^
  File "/Users/zahed/Downloads/BestElectronics/smsCampaign/env/lib/python3.13/site-packages/rest_framework/views.py", line 509, in dispatch
    response = self.handle_exception(exc)
  File "/Users/zahed/Downloads/BestElectronics/smsCampaign/env/lib/python3.13/site-packages/rest_framework/views.py", line 469, in handle_exception
    self.raise_uncaught_exception(exc)
    ~~~~~~~~~~~~~~~~~~~~~~~~~~~~~^^^^^
  File "/Users/zahed/Downloads/BestElectronics/smsCampaign/env/lib/python3.13/site-packages/rest_framework/views.py", line 480, in raise_uncaught_exception
    raise exc
  File "/Users/zahed/Downloads/BestElectronics/smsCampaign/env/lib/python3.13/site-packages/rest_framework/views.py", line 506, in dispatch
    response = handler(request, *args, **kwargs)
  File "/Users/zahed/Downloads/BestElectronics/smsCampaign/campaign/views.py", line 87, in post
    gift_card = GiftCard.objects.get(product_code=product_code)
  File "/Users/zahed/Downloads/BestElectronics/smsCampaign/env/lib/python3.13/site-packages/django/db/models/manager.py", line 87, in manager_method
    return getattr(self.get_queryset(), name)(*args, **kwargs)
           ~~~~~~~~~~~~~~~~~~~~~~~~~~~~~~~~~~^^^^^^^^^^^^^^^^^
  File "/Users/zahed/Downloads/BestElectronics/smsCampaign/env/lib/python3.13/site-packages/django/db/models/query.py", line 652, in get
    raise self.model.MultipleObjectsReturned(
    ...<5 lines>...
    )
campaign.models.GiftCard.MultipleObjectsReturned: get() returned more than one GiftCard -- it returned 2!
"POST //sms/api/gifts/ HTTP/1.1" 500 102839
Internal Server Error: /sms/api/gifts/
Traceback (most recent call last):
  File "/Users/zahed/Downloads/BestElectronics/smsCampaign/env/lib/python3.13/site-packages/django/core/handlers/exception.py", line 55, in inner
    response = get_response(request)
  File "/Users/zahed/Downloads/BestElectronics/smsCampaign/env/lib/python3.13/site-packages/django/core/handlers/base.py", line 197, in _get_response
    response = wrapped_callback(request, *callback_args, **callback_kwargs)
  File "/Users/zahed/Downloads/BestElectronics/smsCampaign/env/lib/python3.13/site-packages/django/views/decorators/csrf.py", line 65, in _view_wrapper
    return view_func(request, *args, **kwargs)
  File "/Users/zahed/Downloads/BestElectronics/smsCampaign/env/lib/python3.13/site-packages/django/views/generic/base.py", line 104, in view
    return self.dispatch(request, *args, **kwargs)
           ~~~~~~~~~~~~~^^^^^^^^^^^^^^^^^^^^^^^^^^
  File "/Users/zahed/Downloads/BestElectronics/smsCampaign/env/lib/python3.13/site-packages/rest_framework/views.py", line 509, in dispatch
    response = self.handle_exception(exc)
  File "/Users/zahed/Downloads/BestElectronics/smsCampaign/env/lib/python3.13/site-packages/rest_framework/views.py", line 469, in handle_exception
    self.raise_uncaught_exception(exc)
    ~~~~~~~~~~~~~~~~~~~~~~~~~~~~~^^^^^
  File "/Users/zahed/Downloads/BestElectronics/smsCampaign/env/lib/python3.13/site-packages/rest_framework/views.py", line 480, in raise_uncaught_exception
    raise exc
  File "/Users/zahed/Downloads/BestElectronics/smsCampaign/env/lib/python3.13/site-packages/rest_framework/views.py", line 506, in dispatch
    response = handler(request, *args, **kwargs)
  File "/Users/zahed/Downloads/BestElectronics/smsCampaign/campaign/views.py", line 87, in post
    gift_card = GiftCard.objects.get(product_code=product_code)
  File "/Users/zahed/Downloads/BestElectronics/smsCampaign/env/lib/python3.13/site-packages/django/db/models/manager.py", line 87, in manager_method
    return getattr(self.get_queryset(), name)(*args, **kwargs)
           ~~~~~~~~~~~~~~~~~~~~~~~~~~~~~~~~~~^^^^^^^^^^^^^^^^^
  File "/Users/zahed/Downloads/BestElectronics/smsCampaign/env/lib/python3.13/site-packages/django/db/models/query.py", line 652, in get
    raise self.model.MultipleObjectsReturned(
    ...<5 lines>...
    )
campaign.models.GiftCard.MultipleObjectsReturned: get() returned more than one GiftCard -- it returned 2!
"POST //sms/api/gifts/ HTTP/1.1" 500 102837
Internal Server Error: /sms/api/gifts/
Traceback (most recent call last):
  File "/Users/zahed/Downloads/BestElectronics/smsCampaign/env/lib/python3.13/site-packages/django/core/handlers/exception.py", line 55, in inner
    response = get_response(request)
  File "/Users/zahed/Downloads/BestElectronics/smsCampaign/env/lib/python3.13/site-packages/django/core/handlers/base.py", line 197, in _get_response
    response = wrapped_callback(request, *callback_args, **callback_kwargs)
  File "/Users/zahed/Downloads/BestElectronics/smsCampaign/env/lib/python3.13/site-packages/django/views/decorators/csrf.py", line 65, in _view_wrapper
    return view_func(request, *args, **kwargs)
  File "/Users/zahed/Downloads/BestElectronics/smsCampaign/env/lib/python3.13/site-packages/django/views/generic/base.py", line 104, in view
    return self.dispatch(request, *args, **kwargs)
           ~~~~~~~~~~~~~^^^^^^^^^^^^^^^^^^^^^^^^^^
  File "/Users/zahed/Downloads/BestElectronics/smsCampaign/env/lib/python3.13/site-packages/rest_framework/views.py", line 509, in dispatch
    response = self.handle_exception(exc)
  File "/Users/zahed/Downloads/BestElectronics/smsCampaign/env/lib/python3.13/site-packages/rest_framework/views.py", line 469, in handle_exception
    self.raise_uncaught_exception(exc)
    ~~~~~~~~~~~~~~~~~~~~~~~~~~~~~^^^^^
  File "/Users/zahed/Downloads/BestElectronics/smsCampaign/env/lib/python3.13/site-packages/rest_framework/views.py", line 480, in raise_uncaught_exception
    raise exc
  File "/Users/zahed/Downloads/BestElectronics/smsCampaign/env/lib/python3.13/site-packages/rest_framework/views.py", line 506, in dispatch
    response = handler(request, *args, **kwargs)
  File "/Users/zahed/Downloads/BestElectronics/smsCampaign/campaign/views.py", line 87, in post
    gift_card = GiftCard.objects.get(product_code=product_code)
  File "/Users/zahed/Downloads/BestElectronics/smsCampaign/env/lib/python3.13/site-packages/django/db/models/manager.py", line 87, in manager_method
    return getattr(self.get_queryset(), name)(*args, **kwargs)
           ~~~~~~~~~~~~~~~~~~~~~~~~~~~~~~~~~~^^^^^^^^^^^^^^^^^
  File "/Users/zahed/Downloads/BestElectronics/smsCampaign/env/lib/python3.13/site-packages/django/db/models/query.py", line 652, in get
    raise self.model.MultipleObjectsReturned(
    ...<5 lines>...
    )
campaign.models.GiftCard.MultipleObjectsReturned: get() returned more than one GiftCard -- it returned 2!
"POST /sms/api/gifts/ HTTP/1.1" 500 102131
Internal Server Error: /sms/api/gifts/
Traceback (most recent call last):
  File "/Users/zahed/Downloads/BestElectronics/smsCampaign/env/lib/python3.13/site-packages/django/core/handlers/exception.py", line 55, in inner
    response = get_response(request)
  File "/Users/zahed/Downloads/BestElectronics/smsCampaign/env/lib/python3.13/site-packages/django/core/handlers/base.py", line 197, in _get_response
    response = wrapped_callback(request, *callback_args, **callback_kwargs)
  File "/Users/zahed/Downloads/BestElectronics/smsCampaign/env/lib/python3.13/site-packages/django/views/decorators/csrf.py", line 65, in _view_wrapper
    return view_func(request, *args, **kwargs)
  File "/Users/zahed/Downloads/BestElectronics/smsCampaign/env/lib/python3.13/site-packages/django/views/generic/base.py", line 104, in view
    return self.dispatch(request, *args, **kwargs)
           ~~~~~~~~~~~~~^^^^^^^^^^^^^^^^^^^^^^^^^^
  File "/Users/zahed/Downloads/BestElectronics/smsCampaign/env/lib/python3.13/site-packages/rest_framework/views.py", line 509, in dispatch
    response = self.handle_exception(exc)
  File "/Users/zahed/Downloads/BestElectronics/smsCampaign/env/lib/python3.13/site-packages/rest_framework/views.py", line 469, in handle_exception
    self.raise_uncaught_exception(exc)
    ~~~~~~~~~~~~~~~~~~~~~~~~~~~~~^^^^^
  File "/Users/zahed/Downloads/BestElectronics/smsCampaign/env/lib/python3.13/site-packages/rest_framework/views.py", line 480, in raise_uncaught_exception
    raise exc
  File "/Users/zahed/Downloads/BestElectronics/smsCampaign/env/lib/python3.13/site-packages/rest_framework/views.py", line 506, in dispatch
    response = handler(request, *args, **kwargs)
  File "/Users/zahed/Downloads/BestElectronics/smsCampaign/campaign/views.py", line 82, in post
    gift_card = GiftCard.objects.get(product_code=product_code)
  File "/Users/zahed/Downloads/BestElectronics/smsCampaign/env/lib/python3.13/site-packages/django/db/models/manager.py", line 87, in manager_method
    return getattr(self.get_queryset(), name)(*args, **kwargs)
           ~~~~~~~~~~~~~~~~~~~~~~~~~~~~~~~~~~^^^^^^^^^^^^^^^^^
  File "/Users/zahed/Downloads/BestElectronics/smsCampaign/env/lib/python3.13/site-packages/django/db/models/query.py", line 652, in get
    raise self.model.MultipleObjectsReturned(
    ...<5 lines>...
    )
campaign.models.GiftCard.MultipleObjectsReturned: get() returned more than one GiftCard -- it returned 2!
"POST /sms/api/gifts/ HTTP/1.1" 500 102131
Internal Server Error: /sms/api/generate-otp/
Traceback (most recent call last):
  File "/Users/zahed/Downloads/BestElectronics/smsCampaign/env/lib/python3.13/site-packages/urllib3/connection.py", line 198, in _new_conn
    sock = connection.create_connection(
        (self._dns_host, self.port),
    ...<2 lines>...
        socket_options=self.socket_options,
    )
  File "/Users/zahed/Downloads/BestElectronics/smsCampaign/env/lib/python3.13/site-packages/urllib3/util/connection.py", line 60, in create_connection
    for res in socket.getaddrinfo(host, port, family, socket.SOCK_STREAM):
               ~~~~~~~~~~~~~~~~~~^^^^^^^^^^^^^^^^^^^^^^^^^^^^^^^^^^^^^^^^
  File "/opt/homebrew/Cellar/python@3.13/3.13.2/Frameworks/Python.framework/Versions/3.13/lib/python3.13/socket.py", line 977, in getaddrinfo
    for res in _socket.getaddrinfo(host, port, family, type, proto, flags):
               ~~~~~~~~~~~~~~~~~~~^^^^^^^^^^^^^^^^^^^^^^^^^^^^^^^^^^^^^^^^
socket.gaierror: [Errno 8] nodename nor servname provided, or not known

The above exception was the direct cause of the following exception:

Traceback (most recent call last):
  File "/Users/zahed/Downloads/BestElectronics/smsCampaign/env/lib/python3.13/site-packages/urllib3/connectionpool.py", line 787, in urlopen
    response = self._make_request(
        conn,
    ...<10 lines>...
        **response_kw,
    )
  File "/Users/zahed/Downloads/BestElectronics/smsCampaign/env/lib/python3.13/site-packages/urllib3/connectionpool.py", line 488, in _make_request
    raise new_e
  File "/Users/zahed/Downloads/BestElectronics/smsCampaign/env/lib/python3.13/site-packages/urllib3/connectionpool.py", line 464, in _make_request
    self._validate_conn(conn)
    ~~~~~~~~~~~~~~~~~~~^^^^^^
  File "/Users/zahed/Downloads/BestElectronics/smsCampaign/env/lib/python3.13/site-packages/urllib3/connectionpool.py", line 1093, in _validate_conn
    conn.connect()
    ~~~~~~~~~~~~^^
  File "/Users/zahed/Downloads/BestElectronics/smsCampaign/env/lib/python3.13/site-packages/urllib3/connection.py", line 704, in connect
    self.sock = sock = self._new_conn()
                       ~~~~~~~~~~~~~~^^
  File "/Users/zahed/Downloads/BestElectronics/smsCampaign/env/lib/python3.13/site-packages/urllib3/connection.py", line 205, in _new_conn
    raise NameResolutionError(self.host, self, e) from e
urllib3.exceptions.NameResolutionError: <urllib3.connection.HTTPSConnection object at 0x10804ad50>: Failed to resolve 'sysadmin.muthobarta.com' ([Errno 8] nodename nor servname provided, or not known)

The above exception was the direct cause of the following exception:

Traceback (most recent call last):
  File "/Users/zahed/Downloads/BestElectronics/smsCampaign/env/lib/python3.13/site-packages/requests/adapters.py", line 667, in send
    resp = conn.urlopen(
        method=request.method,
    ...<9 lines>...
        chunked=chunked,
    )
  File "/Users/zahed/Downloads/BestElectronics/smsCampaign/env/lib/python3.13/site-packages/urllib3/connectionpool.py", line 841, in urlopen
    retries = retries.increment(
        method, url, error=new_e, _pool=self, _stacktrace=sys.exc_info()[2]
    )
  File "/Users/zahed/Downloads/BestElectronics/smsCampaign/env/lib/python3.13/site-packages/urllib3/util/retry.py", line 519, in increment
    raise MaxRetryError(_pool, url, reason) from reason  # type: ignore[arg-type]
    ^^^^^^^^^^^^^^^^^^^^^^^^^^^^^^^^^^^^^^^^^^^^^^^^^^^
urllib3.exceptions.MaxRetryError: HTTPSConnectionPool(host='sysadmin.muthobarta.com', port=443): Max retries exceeded with url: /api/v1/send-sms (Caused by NameResolutionError("<urllib3.connection.HTTPSConnection object at 0x10804ad50>: Failed to resolve 'sysadmin.muthobarta.com' ([Errno 8] nodename nor servname provided, or not known)"))

During handling of the above exception, another exception occurred:

Traceback (most recent call last):
  File "/Users/zahed/Downloads/BestElectronics/smsCampaign/env/lib/python3.13/site-packages/django/core/handlers/exception.py", line 55, in inner
    response = get_response(request)
  File "/Users/zahed/Downloads/BestElectronics/smsCampaign/env/lib/python3.13/site-packages/django/core/handlers/base.py", line 197, in _get_response
    response = wrapped_callback(request, *callback_args, **callback_kwargs)
  File "/Users/zahed/Downloads/BestElectronics/smsCampaign/env/lib/python3.13/site-packages/django/views/decorators/csrf.py", line 65, in _view_wrapper
    return view_func(request, *args, **kwargs)
  File "/Users/zahed/Downloads/BestElectronics/smsCampaign/env/lib/python3.13/site-packages/django/views/generic/base.py", line 104, in view
    return self.dispatch(request, *args, **kwargs)
           ~~~~~~~~~~~~~^^^^^^^^^^^^^^^^^^^^^^^^^^
  File "/Users/zahed/Downloads/BestElectronics/smsCampaign/env/lib/python3.13/site-packages/rest_framework/views.py", line 509, in dispatch
    response = self.handle_exception(exc)
  File "/Users/zahed/Downloads/BestElectronics/smsCampaign/env/lib/python3.13/site-packages/rest_framework/views.py", line 469, in handle_exception
    self.raise_uncaught_exception(exc)
    ~~~~~~~~~~~~~~~~~~~~~~~~~~~~~^^^^^
  File "/Users/zahed/Downloads/BestElectronics/smsCampaign/env/lib/python3.13/site-packages/rest_framework/views.py", line 480, in raise_uncaught_exception
    raise exc
  File "/Users/zahed/Downloads/BestElectronics/smsCampaign/env/lib/python3.13/site-packages/rest_framework/views.py", line 506, in dispatch
    response = handler(request, *args, **kwargs)
  File "/Users/zahed/Downloads/BestElectronics/smsCampaign/campaign/views.py", line 42, in post
    generate_otp(mobile_no)
    ~~~~~~~~~~~~^^^^^^^^^^^
  File "/Users/zahed/Downloads/BestElectronics/smsCampaign/campaign/views.py", line 13, in generate_otp
    response = send_sms(mobile_no, message)
  File "/Users/zahed/Downloads/BestElectronics/smsCampaign/Utility/smsHandlers.py", line 16, in send_sms
    response = requests.post(url, json=data, headers=headers)
  File "/Users/zahed/Downloads/BestElectronics/smsCampaign/env/lib/python3.13/site-packages/requests/api.py", line 115, in post
    return request("post", url, data=data, json=json, **kwargs)
  File "/Users/zahed/Downloads/BestElectronics/smsCampaign/env/lib/python3.13/site-packages/requests/api.py", line 59, in request
    return session.request(method=method, url=url, **kwargs)
           ~~~~~~~~~~~~~~~^^^^^^^^^^^^^^^^^^^^^^^^^^^^^^^^^^
  File "/Users/zahed/Downloads/BestElectronics/smsCampaign/env/lib/python3.13/site-packages/requests/sessions.py", line 589, in request
    resp = self.send(prep, **send_kwargs)
  File "/Users/zahed/Downloads/BestElectronics/smsCampaign/env/lib/python3.13/site-packages/requests/sessions.py", line 703, in send
    r = adapter.send(request, **kwargs)
  File "/Users/zahed/Downloads/BestElectronics/smsCampaign/env/lib/python3.13/site-packages/requests/adapters.py", line 700, in send
    raise ConnectionError(e, request=request)
requests.exceptions.ConnectionError: HTTPSConnectionPool(host='sysadmin.muthobarta.com', port=443): Max retries exceeded with url: /api/v1/send-sms (Caused by NameResolutionError("<urllib3.connection.HTTPSConnection object at 0x10804ad50>: Failed to resolve 'sysadmin.muthobarta.com' ([Errno 8] nodename nor servname provided, or not known)"))
"POST //sms/api/generate-otp/ HTTP/1.1" 500 203251
Internal Server Error: /sms/api/customer-list-create/
Traceback (most recent call last):
  File "/Users/zahed/Downloads/BestElectronics/smsCampaign/env/lib/python3.13/site-packages/django/db/backends/utils.py", line 105, in _execute
    return self.cursor.execute(sql, params)
           ~~~~~~~~~~~~~~~~~~~^^^^^^^^^^^^^
psycopg2.errors.UniqueViolation: duplicate key value violates unique constraint "campaign_customerotp_mobile_no_key"
DETAIL:  Key (mobile_no)=(01700700624) already exists.


The above exception was the direct cause of the following exception:

Traceback (most recent call last):
  File "/Users/zahed/Downloads/BestElectronics/smsCampaign/env/lib/python3.13/site-packages/django/core/handlers/exception.py", line 55, in inner
    response = get_response(request)
  File "/Users/zahed/Downloads/BestElectronics/smsCampaign/env/lib/python3.13/site-packages/django/core/handlers/base.py", line 197, in _get_response
    response = wrapped_callback(request, *callback_args, **callback_kwargs)
  File "/Users/zahed/Downloads/BestElectronics/smsCampaign/env/lib/python3.13/site-packages/django/views/decorators/csrf.py", line 65, in _view_wrapper
    return view_func(request, *args, **kwargs)
  File "/Users/zahed/Downloads/BestElectronics/smsCampaign/env/lib/python3.13/site-packages/django/views/generic/base.py", line 104, in view
    return self.dispatch(request, *args, **kwargs)
           ~~~~~~~~~~~~~^^^^^^^^^^^^^^^^^^^^^^^^^^
  File "/Users/zahed/Downloads/BestElectronics/smsCampaign/env/lib/python3.13/site-packages/rest_framework/views.py", line 509, in dispatch
    response = self.handle_exception(exc)
  File "/Users/zahed/Downloads/BestElectronics/smsCampaign/env/lib/python3.13/site-packages/rest_framework/views.py", line 469, in handle_exception
    self.raise_uncaught_exception(exc)
    ~~~~~~~~~~~~~~~~~~~~~~~~~~~~~^^^^^
  File "/Users/zahed/Downloads/BestElectronics/smsCampaign/env/lib/python3.13/site-packages/rest_framework/views.py", line 480, in raise_uncaught_exception
    raise exc
  File "/Users/zahed/Downloads/BestElectronics/smsCampaign/env/lib/python3.13/site-packages/rest_framework/views.py", line 506, in dispatch
    response = handler(request, *args, **kwargs)
  File "/Users/zahed/Downloads/BestElectronics/smsCampaign/env/lib/python3.13/site-packages/rest_framework/decorators.py", line 50, in handler
    return func(*args, **kwargs)
  File "/Users/zahed/Downloads/BestElectronics/smsCampaign/campaign/views.py", line 120, in customer_list_create
    otp_record = CustomerOTP.objects.create(mobile_no=mobile_no, otp=otp)
  File "/Users/zahed/Downloads/BestElectronics/smsCampaign/env/lib/python3.13/site-packages/django/db/models/manager.py", line 87, in manager_method
    return getattr(self.get_queryset(), name)(*args, **kwargs)
           ~~~~~~~~~~~~~~~~~~~~~~~~~~~~~~~~~~^^^^^^^^^^^^^^^^^
  File "/Users/zahed/Downloads/BestElectronics/smsCampaign/env/lib/python3.13/site-packages/django/db/models/query.py", line 679, in create
    obj.save(force_insert=True, using=self.db)
    ~~~~~~~~^^^^^^^^^^^^^^^^^^^^^^^^^^^^^^^^^^
  File "/Users/zahed/Downloads/BestElectronics/smsCampaign/env/lib/python3.13/site-packages/django/db/models/base.py", line 892, in save
    self.save_base(
    ~~~~~~~~~~~~~~^
        using=using,
        ^^^^^^^^^^^^
    ...<2 lines>...
        update_fields=update_fields,
        ^^^^^^^^^^^^^^^^^^^^^^^^^^^^
    )
    ^
  File "/Users/zahed/Downloads/BestElectronics/smsCampaign/env/lib/python3.13/site-packages/django/db/models/base.py", line 998, in save_base
    updated = self._save_table(
        raw,
    ...<4 lines>...
        update_fields,
    )
  File "/Users/zahed/Downloads/BestElectronics/smsCampaign/env/lib/python3.13/site-packages/django/db/models/base.py", line 1161, in _save_table
    results = self._do_insert(
        cls._base_manager, using, fields, returning_fields, raw
    )
  File "/Users/zahed/Downloads/BestElectronics/smsCampaign/env/lib/python3.13/site-packages/django/db/models/base.py", line 1202, in _do_insert
    return manager._insert(
           ~~~~~~~~~~~~~~~^
        [self],
        ^^^^^^^
    ...<3 lines>...
        raw=raw,
        ^^^^^^^^
    )
    ^
  File "/Users/zahed/Downloads/BestElectronics/smsCampaign/env/lib/python3.13/site-packages/django/db/models/manager.py", line 87, in manager_method
    return getattr(self.get_queryset(), name)(*args, **kwargs)
           ~~~~~~~~~~~~~~~~~~~~~~~~~~~~~~~~~~^^^^^^^^^^^^^^^^^
  File "/Users/zahed/Downloads/BestElectronics/smsCampaign/env/lib/python3.13/site-packages/django/db/models/query.py", line 1847, in _insert
    return query.get_compiler(using=using).execute_sql(returning_fields)
           ~~~~~~~~~~~~~~~~~~~~~~~~~~~~~~~~~~~~~~~~~~~^^^^^^^^^^^^^^^^^^
  File "/Users/zahed/Downloads/BestElectronics/smsCampaign/env/lib/python3.13/site-packages/django/db/models/sql/compiler.py", line 1836, in execute_sql
    cursor.execute(sql, params)
    ~~~~~~~~~~~~~~^^^^^^^^^^^^^
  File "/Users/zahed/Downloads/BestElectronics/smsCampaign/env/lib/python3.13/site-packages/django/db/backends/utils.py", line 122, in execute
    return super().execute(sql, params)
           ~~~~~~~~~~~~~~~^^^^^^^^^^^^^
  File "/Users/zahed/Downloads/BestElectronics/smsCampaign/env/lib/python3.13/site-packages/django/db/backends/utils.py", line 79, in execute
    return self._execute_with_wrappers(
           ~~~~~~~~~~~~~~~~~~~~~~~~~~~^
        sql, params, many=False, executor=self._execute
        ^^^^^^^^^^^^^^^^^^^^^^^^^^^^^^^^^^^^^^^^^^^^^^^
    )
    ^
  File "/Users/zahed/Downloads/BestElectronics/smsCampaign/env/lib/python3.13/site-packages/django/db/backends/utils.py", line 92, in _execute_with_wrappers
    return executor(sql, params, many, context)
  File "/Users/zahed/Downloads/BestElectronics/smsCampaign/env/lib/python3.13/site-packages/django/db/backends/utils.py", line 100, in _execute
    with self.db.wrap_database_errors:
         ^^^^^^^^^^^^^^^^^^^^^^^^^^^^
  File "/Users/zahed/Downloads/BestElectronics/smsCampaign/env/lib/python3.13/site-packages/django/db/utils.py", line 91, in __exit__
    raise dj_exc_value.with_traceback(traceback) from exc_value
  File "/Users/zahed/Downloads/BestElectronics/smsCampaign/env/lib/python3.13/site-packages/django/db/backends/utils.py", line 105, in _execute
    return self.cursor.execute(sql, params)
           ~~~~~~~~~~~~~~~~~~~^^^^^^^^^^^^^
django.db.utils.IntegrityError: duplicate key value violates unique constraint "campaign_customerotp_mobile_no_key"
DETAIL:  Key (mobile_no)=(01700700624) already exists.

"POST /sms/api/customer-list-create/ HTTP/1.1" 500 178024
Internal Server Error: /sms/api/customer-list-create/
Traceback (most recent call last):
  File "/Users/zahed/Downloads/BestElectronics/smsCampaign/env/lib/python3.13/site-packages/django/db/backends/utils.py", line 105, in _execute
    return self.cursor.execute(sql, params)
           ~~~~~~~~~~~~~~~~~~~^^^^^^^^^^^^^
psycopg2.errors.UniqueViolation: duplicate key value violates unique constraint "campaign_customerotp_mobile_no_key"
DETAIL:  Key (mobile_no)=(01700700624) already exists.


The above exception was the direct cause of the following exception:

Traceback (most recent call last):
  File "/Users/zahed/Downloads/BestElectronics/smsCampaign/env/lib/python3.13/site-packages/django/core/handlers/exception.py", line 55, in inner
    response = get_response(request)
  File "/Users/zahed/Downloads/BestElectronics/smsCampaign/env/lib/python3.13/site-packages/django/core/handlers/base.py", line 197, in _get_response
    response = wrapped_callback(request, *callback_args, **callback_kwargs)
  File "/Users/zahed/Downloads/BestElectronics/smsCampaign/env/lib/python3.13/site-packages/django/views/decorators/csrf.py", line 65, in _view_wrapper
    return view_func(request, *args, **kwargs)
  File "/Users/zahed/Downloads/BestElectronics/smsCampaign/env/lib/python3.13/site-packages/django/views/generic/base.py", line 104, in view
    return self.dispatch(request, *args, **kwargs)
           ~~~~~~~~~~~~~^^^^^^^^^^^^^^^^^^^^^^^^^^
  File "/Users/zahed/Downloads/BestElectronics/smsCampaign/env/lib/python3.13/site-packages/rest_framework/views.py", line 509, in dispatch
    response = self.handle_exception(exc)
  File "/Users/zahed/Downloads/BestElectronics/smsCampaign/env/lib/python3.13/site-packages/rest_framework/views.py", line 469, in handle_exception
    self.raise_uncaught_exception(exc)
    ~~~~~~~~~~~~~~~~~~~~~~~~~~~~~^^^^^
  File "/Users/zahed/Downloads/BestElectronics/smsCampaign/env/lib/python3.13/site-packages/rest_framework/views.py", line 480, in raise_uncaught_exception
    raise exc
  File "/Users/zahed/Downloads/BestElectronics/smsCampaign/env/lib/python3.13/site-packages/rest_framework/views.py", line 506, in dispatch
    response = handler(request, *args, **kwargs)
  File "/Users/zahed/Downloads/BestElectronics/smsCampaign/env/lib/python3.13/site-packages/rest_framework/decorators.py", line 50, in handler
    return func(*args, **kwargs)
  File "/Users/zahed/Downloads/BestElectronics/smsCampaign/campaign/views.py", line 120, in customer_list_create
    otp_record = CustomerOTP.objects.create(mobile_no=mobile_no, otp=otp)
  File "/Users/zahed/Downloads/BestElectronics/smsCampaign/env/lib/python3.13/site-packages/django/db/models/manager.py", line 87, in manager_method
    return getattr(self.get_queryset(), name)(*args, **kwargs)
           ~~~~~~~~~~~~~~~~~~~~~~~~~~~~~~~~~~^^^^^^^^^^^^^^^^^
  File "/Users/zahed/Downloads/BestElectronics/smsCampaign/env/lib/python3.13/site-packages/django/db/models/query.py", line 679, in create
    obj.save(force_insert=True, using=self.db)
    ~~~~~~~~^^^^^^^^^^^^^^^^^^^^^^^^^^^^^^^^^^
  File "/Users/zahed/Downloads/BestElectronics/smsCampaign/env/lib/python3.13/site-packages/django/db/models/base.py", line 892, in save
    self.save_base(
    ~~~~~~~~~~~~~~^
        using=using,
        ^^^^^^^^^^^^
    ...<2 lines>...
        update_fields=update_fields,
        ^^^^^^^^^^^^^^^^^^^^^^^^^^^^
    )
    ^
  File "/Users/zahed/Downloads/BestElectronics/smsCampaign/env/lib/python3.13/site-packages/django/db/models/base.py", line 998, in save_base
    updated = self._save_table(
        raw,
    ...<4 lines>...
        update_fields,
    )
  File "/Users/zahed/Downloads/BestElectronics/smsCampaign/env/lib/python3.13/site-packages/django/db/models/base.py", line 1161, in _save_table
    results = self._do_insert(
        cls._base_manager, using, fields, returning_fields, raw
    )
  File "/Users/zahed/Downloads/BestElectronics/smsCampaign/env/lib/python3.13/site-packages/django/db/models/base.py", line 1202, in _do_insert
    return manager._insert(
           ~~~~~~~~~~~~~~~^
        [self],
        ^^^^^^^
    ...<3 lines>...
        raw=raw,
        ^^^^^^^^
    )
    ^
  File "/Users/zahed/Downloads/BestElectronics/smsCampaign/env/lib/python3.13/site-packages/django/db/models/manager.py", line 87, in manager_method
    return getattr(self.get_queryset(), name)(*args, **kwargs)
           ~~~~~~~~~~~~~~~~~~~~~~~~~~~~~~~~~~^^^^^^^^^^^^^^^^^
  File "/Users/zahed/Downloads/BestElectronics/smsCampaign/env/lib/python3.13/site-packages/django/db/models/query.py", line 1847, in _insert
    return query.get_compiler(using=using).execute_sql(returning_fields)
           ~~~~~~~~~~~~~~~~~~~~~~~~~~~~~~~~~~~~~~~~~~~^^^^^^^^^^^^^^^^^^
  File "/Users/zahed/Downloads/BestElectronics/smsCampaign/env/lib/python3.13/site-packages/django/db/models/sql/compiler.py", line 1836, in execute_sql
    cursor.execute(sql, params)
    ~~~~~~~~~~~~~~^^^^^^^^^^^^^
  File "/Users/zahed/Downloads/BestElectronics/smsCampaign/env/lib/python3.13/site-packages/django/db/backends/utils.py", line 122, in execute
    return super().execute(sql, params)
           ~~~~~~~~~~~~~~~^^^^^^^^^^^^^
  File "/Users/zahed/Downloads/BestElectronics/smsCampaign/env/lib/python3.13/site-packages/django/db/backends/utils.py", line 79, in execute
    return self._execute_with_wrappers(
           ~~~~~~~~~~~~~~~~~~~~~~~~~~~^
        sql, params, many=False, executor=self._execute
        ^^^^^^^^^^^^^^^^^^^^^^^^^^^^^^^^^^^^^^^^^^^^^^^
    )
    ^
  File "/Users/zahed/Downloads/BestElectronics/smsCampaign/env/lib/python3.13/site-packages/django/db/backends/utils.py", line 92, in _execute_with_wrappers
    return executor(sql, params, many, context)
  File "/Users/zahed/Downloads/BestElectronics/smsCampaign/env/lib/python3.13/site-packages/django/db/backends/utils.py", line 100, in _execute
    with self.db.wrap_database_errors:
         ^^^^^^^^^^^^^^^^^^^^^^^^^^^^
  File "/Users/zahed/Downloads/BestElectronics/smsCampaign/env/lib/python3.13/site-packages/django/db/utils.py", line 91, in __exit__
    raise dj_exc_value.with_traceback(traceback) from exc_value
  File "/Users/zahed/Downloads/BestElectronics/smsCampaign/env/lib/python3.13/site-packages/django/db/backends/utils.py", line 105, in _execute
    return self.cursor.execute(sql, params)
           ~~~~~~~~~~~~~~~~~~~^^^^^^^^^^^^^
django.db.utils.IntegrityError: duplicate key value violates unique constraint "campaign_customerotp_mobile_no_key"
DETAIL:  Key (mobile_no)=(01700700624) already exists.

"POST /sms/api/customer-list-create/ HTTP/1.1" 500 178024
Internal Server Error: /sms/api/customer-list-create/
Traceback (most recent call last):
  File "/Users/zahed/Downloads/BestElectronics/smsCampaign/env/lib/python3.13/site-packages/django/db/backends/utils.py", line 105, in _execute
    return self.cursor.execute(sql, params)
           ~~~~~~~~~~~~~~~~~~~^^^^^^^^^^^^^
psycopg2.errors.UniqueViolation: duplicate key value violates unique constraint "campaign_customerotp_mobile_no_key"
DETAIL:  Key (mobile_no)=(01700700624) already exists.


The above exception was the direct cause of the following exception:

Traceback (most recent call last):
  File "/Users/zahed/Downloads/BestElectronics/smsCampaign/env/lib/python3.13/site-packages/django/core/handlers/exception.py", line 55, in inner
    response = get_response(request)
  File "/Users/zahed/Downloads/BestElectronics/smsCampaign/env/lib/python3.13/site-packages/django/core/handlers/base.py", line 197, in _get_response
    response = wrapped_callback(request, *callback_args, **callback_kwargs)
  File "/Users/zahed/Downloads/BestElectronics/smsCampaign/env/lib/python3.13/site-packages/django/views/decorators/csrf.py", line 65, in _view_wrapper
    return view_func(request, *args, **kwargs)
  File "/Users/zahed/Downloads/BestElectronics/smsCampaign/env/lib/python3.13/site-packages/django/views/generic/base.py", line 104, in view
    return self.dispatch(request, *args, **kwargs)
           ~~~~~~~~~~~~~^^^^^^^^^^^^^^^^^^^^^^^^^^
  File "/Users/zahed/Downloads/BestElectronics/smsCampaign/env/lib/python3.13/site-packages/rest_framework/views.py", line 509, in dispatch
    response = self.handle_exception(exc)
  File "/Users/zahed/Downloads/BestElectronics/smsCampaign/env/lib/python3.13/site-packages/rest_framework/views.py", line 469, in handle_exception
    self.raise_uncaught_exception(exc)
    ~~~~~~~~~~~~~~~~~~~~~~~~~~~~~^^^^^
  File "/Users/zahed/Downloads/BestElectronics/smsCampaign/env/lib/python3.13/site-packages/rest_framework/views.py", line 480, in raise_uncaught_exception
    raise exc
  File "/Users/zahed/Downloads/BestElectronics/smsCampaign/env/lib/python3.13/site-packages/rest_framework/views.py", line 506, in dispatch
    response = handler(request, *args, **kwargs)
  File "/Users/zahed/Downloads/BestElectronics/smsCampaign/env/lib/python3.13/site-packages/rest_framework/decorators.py", line 50, in handler
    return func(*args, **kwargs)
  File "/Users/zahed/Downloads/BestElectronics/smsCampaign/campaign/views.py", line 120, in customer_list_create
    otp_record = CustomerOTP.objects.create(mobile_no=mobile_no, otp=otp)
  File "/Users/zahed/Downloads/BestElectronics/smsCampaign/env/lib/python3.13/site-packages/django/db/models/manager.py", line 87, in manager_method
    return getattr(self.get_queryset(), name)(*args, **kwargs)
           ~~~~~~~~~~~~~~~~~~~~~~~~~~~~~~~~~~^^^^^^^^^^^^^^^^^
  File "/Users/zahed/Downloads/BestElectronics/smsCampaign/env/lib/python3.13/site-packages/django/db/models/query.py", line 679, in create
    obj.save(force_insert=True, using=self.db)
    ~~~~~~~~^^^^^^^^^^^^^^^^^^^^^^^^^^^^^^^^^^
  File "/Users/zahed/Downloads/BestElectronics/smsCampaign/env/lib/python3.13/site-packages/django/db/models/base.py", line 892, in save
    self.save_base(
    ~~~~~~~~~~~~~~^
        using=using,
        ^^^^^^^^^^^^
    ...<2 lines>...
        update_fields=update_fields,
        ^^^^^^^^^^^^^^^^^^^^^^^^^^^^
    )
    ^
  File "/Users/zahed/Downloads/BestElectronics/smsCampaign/env/lib/python3.13/site-packages/django/db/models/base.py", line 998, in save_base
    updated = self._save_table(
        raw,
    ...<4 lines>...
        update_fields,
    )
  File "/Users/zahed/Downloads/BestElectronics/smsCampaign/env/lib/python3.13/site-packages/django/db/models/base.py", line 1161, in _save_table
    results = self._do_insert(
        cls._base_manager, using, fields, returning_fields, raw
    )
  File "/Users/zahed/Downloads/BestElectronics/smsCampaign/env/lib/python3.13/site-packages/django/db/models/base.py", line 1202, in _do_insert
    return manager._insert(
           ~~~~~~~~~~~~~~~^
        [self],
        ^^^^^^^
    ...<3 lines>...
        raw=raw,
        ^^^^^^^^
    )
    ^
  File "/Users/zahed/Downloads/BestElectronics/smsCampaign/env/lib/python3.13/site-packages/django/db/models/manager.py", line 87, in manager_method
    return getattr(self.get_queryset(), name)(*args, **kwargs)
           ~~~~~~~~~~~~~~~~~~~~~~~~~~~~~~~~~~^^^^^^^^^^^^^^^^^
  File "/Users/zahed/Downloads/BestElectronics/smsCampaign/env/lib/python3.13/site-packages/django/db/models/query.py", line 1847, in _insert
    return query.get_compiler(using=using).execute_sql(returning_fields)
           ~~~~~~~~~~~~~~~~~~~~~~~~~~~~~~~~~~~~~~~~~~~^^^^^^^^^^^^^^^^^^
  File "/Users/zahed/Downloads/BestElectronics/smsCampaign/env/lib/python3.13/site-packages/django/db/models/sql/compiler.py", line 1836, in execute_sql
    cursor.execute(sql, params)
    ~~~~~~~~~~~~~~^^^^^^^^^^^^^
  File "/Users/zahed/Downloads/BestElectronics/smsCampaign/env/lib/python3.13/site-packages/django/db/backends/utils.py", line 122, in execute
    return super().execute(sql, params)
           ~~~~~~~~~~~~~~~^^^^^^^^^^^^^
  File "/Users/zahed/Downloads/BestElectronics/smsCampaign/env/lib/python3.13/site-packages/django/db/backends/utils.py", line 79, in execute
    return self._execute_with_wrappers(
           ~~~~~~~~~~~~~~~~~~~~~~~~~~~^
        sql, params, many=False, executor=self._execute
        ^^^^^^^^^^^^^^^^^^^^^^^^^^^^^^^^^^^^^^^^^^^^^^^
    )
    ^
  File "/Users/zahed/Downloads/BestElectronics/smsCampaign/env/lib/python3.13/site-packages/django/db/backends/utils.py", line 92, in _execute_with_wrappers
    return executor(sql, params, many, context)
  File "/Users/zahed/Downloads/BestElectronics/smsCampaign/env/lib/python3.13/site-packages/django/db/backends/utils.py", line 100, in _execute
    with self.db.wrap_database_errors:
         ^^^^^^^^^^^^^^^^^^^^^^^^^^^^
  File "/Users/zahed/Downloads/BestElectronics/smsCampaign/env/lib/python3.13/site-packages/django/db/utils.py", line 91, in __exit__
    raise dj_exc_value.with_traceback(traceback) from exc_value
  File "/Users/zahed/Downloads/BestElectronics/smsCampaign/env/lib/python3.13/site-packages/django/db/backends/utils.py", line 105, in _execute
    return self.cursor.execute(sql, params)
           ~~~~~~~~~~~~~~~~~~~^^^^^^^^^^^^^
django.db.utils.IntegrityError: duplicate key value violates unique constraint "campaign_customerotp_mobile_no_key"
DETAIL:  Key (mobile_no)=(01700700624) already exists.

"POST /sms/api/customer-list-create/ HTTP/1.1" 500 178024
Internal Server Error: /sms/api/redeem-discount/
"POST /sms/api/redeem-discount/ HTTP/1.1" 500 52
Internal Server Error: /sms/api/redeem-discount/
Internal Server Error: /sms/api/redeem-discount/
"POST /sms/api/redeem-discount/ HTTP/1.1" 500 52
